Workbook

Sheet 00_HOME
A1: P95 PERSONAL OPERATING SYSTEM — AGENDA + ASISTENTE MÓVIL 2026
A3: Google Sheets = cerebro operativo · Calendar = reloj · WhatsApp = terminal móvil. El objetivo es operar con estándares internos P95 medibles, sin prometer un percentil externo garantizado.
A6: ÍNDICE P95 | D6: EJECUCIÓN HOY | G6: FOCO HOY (MIN) | I6: VENCIDAS
A7: ='08_DASHBOARD'!A4 -> 13.1 | D7: ='08_DASHBOARD'!D4 -> 0 | G7: ='08_DASHBOARD'!G4 -> 0 | I7: ='08_DASHBOARD'!J4 -> 3
A10: RUTINA DE OPERACIÓN
A11: Momento | B11: Acción | C11: Canal | D11: Regla P95 | E11: Resultado
A12: Inicio del día | B12: Revisar HOY + Top 3 + bloque de foco | C12: WhatsApp / Agenda | D12: No abrir correo/chat antes de definir Top 3 | E12: Dirección clara
A13: Durante el día | B13: Trabajar por bloques; capturar sin cambiar de tarea | C13: WhatsApp CAPTURA / Inbox | D13: Una tarea cognitiva a la vez | E13: Menos cambio de contexto
A14: Antes de reunión | B14: Definir propósito, decisión y prelectura | C14: Reuniones | D14: Sin propósito/resultado no entra | E14: Reuniones útiles
A15: Cierre | B15: Cerrar, reprogramar o delegar todo lo abierto | C15: WhatsApp CIERRE | D15: Cero pendientes ambiguos | E15: Backlog sano
A16: Viernes | B16: Revisión semanal + plan siguiente | C16: Reportes | D16: 100% revisión semanal | E16: Mejora continua
A18: COMANDOS DE WHATSAPP
A19: Comando | B19: Qué hace | C19: Ejemplo
A20: HOY | B20: Prioridades, reuniones y vencimientos | C20: HOY
A21: CAPTURA <texto> | B21: Guarda en Inbox sin romper foco | C21: CAPTURA llamar proveedor
A22: HECHO <ID> | B22: Cierra actividad | C22: HECHO AG-0007
A23: POSPONER <ID> <min> | B23: Reprograma | C23: POSPONER AG-0007 30
A24: FOCO <min> <texto> | B24: Crea bloque inmediato | C24: FOCO 60 cerrar informe
A25: CIERRE | B25: Cierre ejecutivo diario | C25: CIERRE
A26: SEMANA | B26: Resumen semanal | C26: SEMANA

Sheet 01_INBOX
A1: 01 — INBOX UNIVERSAL / CAPTURA RÁPIDA
A3: Capturado en | B3: Fuente | C3: Tipo | D3: Entrada | E3: Contexto | F3: ¿Acción? | G3: Fecha límite | H3: Estimado min | I3: Prioridad | J3: Procesado | K3: Agenda ID | L3: Notas
A4: 46255.389 | B4: WhatsApp | C4: Idea | D4: Ejemplo: preparar propuesta comercial | E4: Oficina | F4: Sí | G4: 46255 | H4: 30 | I4: P2 | J4: No | L4: Fila ejemplo; puede borrarse

Sheet 02_AGENDA
A1: 02 — AGENDA MAESTRA / EJECUCIÓN
A3: ID | B3: Fecha | C3: Inicio | D3: Fin | E3: Tipo | F3: Actividad | G3: Resultado esperado | H3: Objetivo/OKR | I3: Prioridad | J3: Impacto 1-5 | K3: Urgencia 1-5 | L3: Energía | M3: Estado | N3: Responsable | O3: Delegable | P3: Recurrente ID | Q3: Recordatorio min | R3: WhatsApp | S3: Calendar | T3: Event ID | U3: Fecha límite | V3: Completado en | W3: Min plan | X3: Min reales | Y3: Score prioridad | Z3: Foco profundo | AA3: Contexto/Ubicación | AB3: Notas
A4: AG-0001 | B4: 46255 | C4: 0.29166667 | D4: 0.30208333 | E4: Administrativo | F4: Plan diario + Top 3 | G4: Top 3 definidos y agenda saneada | I4: P1 | J4: 5 | K4: 5 | L4: Alta | M4: Hecho | N4: Yo | O4: No | P4: R-001 | Q4: 10 | R4: Sí | S4: Sí | U4: 46255 | V4: 46255.302 | W4: =IF(OR(C4="",D4=""),"",ROUND((D4-C4)*1440,0)) -> 15 | X4: 15 | Y4: =IF(A4="","",ROUND((J4*4+K4*3+IF(I4="P1",5,IF(I4="P2",4,IF(I4="P3",3,2)))*2+IF(Z4="Sí",5,3))*2,0)) -> 96 | Z4: No | AA4: Oficina | AB4: Plantilla
A5: AG-0002 | B5: 46255 | C5: 0.3125 | D5: 0.375 | E5: Foco | F5: Bloque de foco #1 | G5: Avance verificable del objetivo principal | I5: P1 | J5: 5 | K5: 4 | L5: Alta | M5: En curso | N5: Yo | O5: No | P5: R-002 | Q5: 10 | R5: Sí | S5: Sí | U5: 46255 | W5: =IF(OR(C5="",D5=""),"",ROUND((D5-C5)*1440,0)) -> 90 | X5: 0 | Y5: =IF(A5="","",ROUND((J5*4+K5*3+IF(I5="P2",5,IF(I5="P3",4,IF(I5="P4",3,2)))*2+IF(Z5="Sí",5,3))*2,0)) -> 82 | Z5: Sí | AA5: Sin interrupciones | AB5: Reemplazar por prioridad real
A6: AG-0003 | B6: 46255 | C6: 0.48958333 | D6: 0.5 | E6: Administrativo | F6: Procesar INBOX | G6: Inbox procesado/delegado/agendado | I6: P2 | J6: 4 | K6: 3 | L6: Media | M6: Pendiente | N6: Yo | O6: Sí | P6: R-003 | Q6: 5 | R6: Sí | S6: Sí | U6: 46255 | W6: =IF(OR(C6="",D6=""),"",ROUND((D6-C6)*1440,0)) -> 15 | X6: 0 | Y6: =IF(A6="","",ROUND((J6*4+K6*3+IF(I6="P3",5,IF(I6="P4",4,IF(I6="P5",3,2)))*2+IF(Z6="Sí",5,3))*2,0)) -> 64 | Z6: No | AA6: Móvil/Oficina
A7: AG-0004 | B7: 46255 | C7: 0.72916667 | D7: 0.73958333 | E7: Administrativo | F7: Cierre diario | G7: Pendientes cerrados o reprogramados | I7: P1 | J7: 5 | K7: 4 | L7: Media | M7: Pendiente | N7: Yo | O7: No | P7: R-004 | Q7: 10 | R7: Sí | S7: Sí | U7: 46255 | W7: =IF(OR(C7="",D7=""),"",ROUND((D7-C7)*1440,0)) -> 15 | X7: 0 | Y7: =IF(A7="","",ROUND((J7*4+K7*3+IF(I7="P4",5,IF(I7="P5",4,IF(I7="P6",3,2)))*2+IF(Z7="Sí",5,3))*2,0)) -> 78 | Z7: No | AA7: Móvil
B8: 46267 | C8: 0.25 | D8: 0.66666667 | E8: Administrativo | F8: Diligenciamiento de los pagos de caña | G8: Base liquidación de cañas Septiembre | W8: =IF(OR(C8="",D8=""),"",ROUND((D8-C8)*1440,0)) -> 600 | Y8: =IF(A8="","",ROUND((J8*4+K8*3+IF(I8="P5",5,IF(I8="P6",4,IF(I8="P7",3,2)))*2+IF(Z8="Sí",5,3))*2,0))
F9: 3 Modelos de Formatos - Venta Caña | W9: =IF(OR(C9="",D9=""),"",ROUND((D9-C9)*1440,0)) | Y9: =IF(A9="","",ROUND((J9*4+K9*3+IF(I9="P6",5,IF(I9="P7",4,IF(I9="P8",3,2)))*2+IF(Z9="Sí",5,3))*2,0))
F10: Reunión Con Molinares - INCAUCA | W10: =IF(OR(C10="",D10=""),"",ROUND((D10-C10)*1440,0)) | Y10: =IF(A10="","",ROUND((J10*4+K10*3+IF(I10="P7",5,IF(I10="P8",4,IF(I10="P9",3,2)))*2+IF(Z10="Sí",5,3))*2,0))
F11: Reunión Con Castilla - CASTILLA | W11: =IF(OR(C11="",D11=""),"",ROUND((D11-C11)*1440,0)) | Y11: =IF(A11="","",ROUND((J11*4+K11*3+IF(I11="P8",5,IF(I11="P9",4,IF(I11="P10",3,2)))*2+IF(Z11="Sí",5,3))*2,0))
F12: Informar a Bernardo que hasta hoy labora | W12: =IF(OR(C12="",D12=""),"",ROUND((D12-C12)*1440,0)) | Y12: =IF(A12="","",ROUND((J12*4+K12*3+IF(I12="P9",5,IF(I12="P10",4,IF(I12="P11",3,2)))*2+IF(Z12="Sí",5,3))*2,0))
F13: Subir Acreencias - Hector Fabio Riascos C. | W13: =IF(OR(C13="",D13=""),"",ROUND((D13-C13)*1440,0)) | Y13: =IF(A13="","",ROUND((J13*4+K13*3+IF(I13="P10",5,IF(I13="P11",4,IF(I13="P12",3,2)))*2+IF(Z13="Sí",5,3))*2,0))
W14: =IF(OR(C14="",D14=""),"",ROUND((D14-C14)*1440,0)) | Y14: =IF(A14="","",ROUND((J14*4+K14*3+IF(I14="P11",5,IF(I14="P12",4,IF(I14="P13",3,2)))*2+IF(Z14="Sí",5,3))*2,0))
W15: =IF(OR(C15="",D15=""),"",ROUND((D15-C15)*1440,0)) | Y15: =IF(A15="","",ROUND((J15*4+K15*3+IF(I15="P12",5,IF(I15="P13",4,IF(I15="P14",3,2)))*2+IF(Z15="Sí",5,3))*2,0))
W16: =IF(OR(C16="",D16=""),"",ROUND((D16-C16)*1440,0)) | Y16: =IF(A16="","",ROUND((J16*4+K16*3+IF(I16="P13",5,IF(I16="P14",4,IF(I16="P15",3,2)))*2+IF(Z16="Sí",5,3))*2,0))
W17: =IF(OR(C17="",D17=""),"",ROUND((D17-C17)*1440,0)) | Y17: =IF(A17="","",ROUND((J17*4+K17*3+IF(I17="P14",5,IF(I17="P15",4,IF(I17="P16",3,2)))*2+IF(Z17="Sí",5,3))*2,0))
W18: =IF(OR(C18="",D18=""),"",ROUND((D18-C18)*1440,0)) | Y18: =IF(A18="","",ROUND((J18*4+K18*3+IF(I18="P15",5,IF(I18="P16",4,IF(I18="P17",3,2)))*2+IF(Z18="Sí",5,3))*2,0))
W19: =IF(OR(C19="",D19=""),"",ROUND((D19-C19)*1440,0)) | Y19: =IF(A19="","",ROUND((J19*4+K19*3+IF(I19="P16",5,IF(I19="P17",4,IF(I19="P18",3,2)))*2+IF(Z19="Sí",5,3))*2,0))
W20: =IF(OR(C20="",D20=""),"",ROUND((D20-C20)*1440,0)) | Y20: =IF(A20="","",ROUND((J20*4+K20*3+IF(I20="P17",5,IF(I20="P18",4,IF(I20="P19",3,2)))*2+IF(Z20="Sí",5,3))*2,0))
W21: =IF(OR(C21="",D21=""),"",ROUND((D21-C21)*1440,0)) | Y21: =IF(A21="","",ROUND((J21*4+K21*3+IF(I21="P18",5,IF(I21="P19",4,IF(I21="P20",3,2)))*2+IF(Z21="Sí",5,3))*2,0))
W22: =IF(OR(C22="",D22=""),"",ROUND((D22-C22)*1440,0)) | Y22: =IF(A22="","",ROUND((J22*4+K22*3+IF(I22="P19",5,IF(I22="P20",4,IF(I22="P21",3,2)))*2+IF(Z22="Sí",5,3))*2,0))
W23: =IF(OR(C23="",D23=""),"",ROUND((D23-C23)*1440,0)) | Y23: =IF(A23="","",ROUND((J23*4+K23*3+IF(I23="P20",5,IF(I23="P21",4,IF(I23="P22",3,2)))*2+IF(Z23="Sí",5,3))*2,0))
W24: =IF(OR(C24="",D24=""),"",ROUND((D24-C24)*1440,0)) | Y24: =IF(A24="","",ROUND((J24*4+K24*3+IF(I24="P21",5,IF(I24="P22",4,IF(I24="P23",3,2)))*2+IF(Z24="Sí",5,3))*2,0))
W25: =IF(OR(C25="",D25=""),"",ROUND((D25-C25)*1440,0)) | Y25: =IF(A25="","",ROUND((J25*4+K25*3+IF(I25="P22",5,IF(I25="P23",4,IF(I25="P24",3,2)))*2+IF(Z25="Sí",5,3))*2,0))
W26: =IF(OR(C26="",D26=""),"",ROUND((D26-C26)*1440,0)) | Y26: =IF(A26="","",ROUND((J26*4+K26*3+IF(I26="P23",5,IF(I26="P24",4,IF(I26="P25",3,2)))*2+IF(Z26="Sí",5,3))*2,0))
W27: =IF(OR(C27="",D27=""),"",ROUND((D27-C27)*1440,0)) | Y27: =IF(A27="","",ROUND((J27*4+K27*3+IF(I27="P24",5,IF(I27="P25",4,IF(I27="P26",3,2)))*2+IF(Z27="Sí",5,3))*2,0))
W28: =IF(OR(C28="",D28=""),"",ROUND((D28-C28)*1440,0)) | Y28: =IF(A28="","",ROUND((J28*4+K28*3+IF(I28="P25",5,IF(I28="P26",4,IF(I28="P27",3,2)))*2+IF(Z28="Sí",5,3))*2,0))
W29: =IF(OR(C29="",D29=""),"",ROUND((D29-C29)*1440,0)) | Y29: =IF(A29="","",ROUND((J29*4+K29*3+IF(I29="P26",5,IF(I29="P27",4,IF(I29="P28",3,2)))*2+IF(Z29="Sí",5,3))*2,0))
W30: =IF(OR(C30="",D30=""),"",ROUND((D30-C30)*1440,0)) | Y30: =IF(A30="","",ROUND((J30*4+K30*3+IF(I30="P27",5,IF(I30="P28",4,IF(I30="P29",3,2)))*2+IF(Z30="Sí",5,3))*2,0))
W31: =IF(OR(C31="",D31=""),"",ROUND((D31-C31)*1440,0)) | Y31: =IF(A31="","",ROUND((J31*4+K31*3+IF(I31="P28",5,IF(I31="P29",4,IF(I31="P30",3,2)))*2+IF(Z31="Sí",5,3))*2,0))
W32: =IF(OR(C32="",D32=""),"",ROUND((D32-C32)*1440,0)) | Y32: =IF(A32="","",ROUND((J32*4+K32*3+IF(I32="P29",5,IF(I32="P30",4,IF(I32="P31",3,2)))*2+IF(Z32="Sí",5,3))*2,0))
W33: =IF(OR(C33="",D33=""),"",ROUND((D33-C33)*1440,0)) | Y33: =IF(A33="","",ROUND((J33*4+K33*3+IF(I33="P30",5,IF(I33="P31",4,IF(I33="P32",3,2)))*2+IF(Z33="Sí",5,3))*2,0))
W34: =IF(OR(C34="",D34=""),"",ROUND((D34-C34)*1440,0)) | Y34: =IF(A34="","",ROUND((J34*4+K34*3+IF(I34="P31",5,IF(I34="P32",4,IF(I34="P33",3,2)))*2+IF(Z34="Sí",5,3))*2,0))
W35: =IF(OR(C35="",D35=""),"",ROUND((D35-C35)*1440,0)) | Y35: =IF(A35="","",ROUND((J35*4+K35*3+IF(I35="P32",5,IF(I35="P33",4,IF(I35="P34",3,2)))*2+IF(Z35="Sí",5,3))*2,0))
W36: =IF(OR(C36="",D36=""),"",ROUND((D36-C36)*1440,0)) | Y36: =IF(A36="","",ROUND((J36*4+K36*3+IF(I36="P33",5,IF(I36="P34",4,IF(I36="P35",3,2)))*2+IF(Z36="Sí",5,3))*2,0))
W37: =IF(OR(C37="",D37=""),"",ROUND((D37-C37)*1440,0)) | Y37: =IF(A37="","",ROUND((J37*4+K37*3+IF(I37="P34",5,IF(I37="P35",4,IF(I37="P36",3,2)))*2+IF(Z37="Sí",5,3))*2,0))
W38: =IF(OR(C38="",D38=""),"",ROUND((D38-C38)*1440,0)) | Y38: =IF(A38="","",ROUND((J38*4+K38*3+IF(I38="P35",5,IF(I38="P36",4,IF(I38="P37",3,2)))*2+IF(Z38="Sí",5,3))*2,0))
W39: =IF(OR(C39="",D39=""),"",ROUND((D39-C39)*1440,0)) | Y39: =IF(A39="","",ROUND((J39*4+K39*3+IF(I39="P36",5,IF(I39="P37",4,IF(I39="P38",3,2)))*2+IF(Z39="Sí",5,3))*2,0))
W40: =IF(OR(C40="",D40=""),"",ROUND((D40-C40)*1440,0)) | Y40: =IF(A40="","",ROUND((J40*4+K40*3+IF(I40="P37",5,IF(I40="P38",4,IF(I40="P39",3,2)))*2+IF(Z40="Sí",5,3))*2,0))
W41: =IF(OR(C41="",D41=""),"",ROUND((D41-C41)*1440,0)) | Y41: =IF(A41="","",ROUND((J41*4+K41*3+IF(I41="P38",5,IF(I41="P39",4,IF(I41="P40",3,2)))*2+IF(Z41="Sí",5,3))*2,0))
...

Sheet 03_RECURRENCIAS
A1: 03 — ACTIVIDADES RECURRENTES
A3: Recurrente ID | B3: Activo | C3: Frecuencia | D3: Regla día | E3: Hora | F3: Duración min | G3: Tipo | H3: Actividad | I3: Resultado esperado | J3: OKR | K3: Prioridad | L3: Impacto | M3: Urgencia | N3: Foco profundo | O3: Recordatorio min | P3: WhatsApp | Q3: Calendar | R3: Responsable | S3: Inicio vigencia | T3: Fin vigencia | U3: Última generación | V3: Notas
A4: R-001 | B4: Sí | C4: LABORABLES | D4: LUN-MAR-MIE-JUE-VIE | E4: 0.29166667 | F4: 15 | G4: Administrativo | H4: Plan diario + Top 3 | I4: Top 3 definidos | K4: P1 | L4: 5 | M4: 5 | N4: No | O4: 10 | P4: Sí | Q4: Sí | R4: Yo | S4: 46255 | V4: Arranque
A5: R-002 | B5: Sí | C5: LABORABLES | D5: LUN-MAR-MIE-JUE-VIE | E5: 0.3125 | F5: 90 | G5: Foco | H5: Bloque de foco #1 | I5: Avance principal | K5: P1 | L5: 5 | M5: 4 | N5: Sí | O5: 10 | P5: Sí | Q5: Sí | R5: Yo | S5: 46255 | V5: Proteger de reuniones
A6: R-003 | B6: Sí | C6: LABORABLES | D6: LUN-MAR-MIE-JUE-VIE | E6: 0.48958333 | F6: 15 | G6: Administrativo | H6: Procesar INBOX | I6: Inbox a cero ambiguo | K6: P2 | L6: 4 | M6: 3 | N6: No | O6: 5 | P6: Sí | Q6: Sí | R6: Yo | S6: 46255 | V6: Batching
A7: R-004 | B7: Sí | C7: LABORABLES | D7: LUN-MAR-MIE-JUE-VIE | E7: 0.72916667 | F7: 15 | G7: Administrativo | H7: Cierre diario | I7: Todo cerrado/reprogramado | K7: P1 | L7: 5 | M7: 4 | N7: No | O7: 10 | P7: Sí | Q7: Sí | R7: Yo | S7: 46255 | V7: Cierre cognitivo
A8: R-005 | B8: Sí | C8: SEMANAL | D8: VIE | E8: 0.6875 | F8: 45 | G8: Reporte | H8: Revisión semanal P95 | I8: Informe y plan siguiente semana | K8: P1 | L8: 5 | M8: 4 | N8: No | O8: 30 | P8: Sí | Q8: Sí | R8: Yo | S8: 46255 | V8: 100% cumplimiento
A9: R-006 | B9: Sí | C9: MENSUAL | D9: 1 | E9: 0.33333333 | F9: 60 | G9: Reporte | H9: Revisión mensual y OKR | I9: Objetivos actualizados | K9: P1 | L9: 5 | M9: 4 | N9: Sí | O9: 60 | P9: Sí | Q9: Sí | R9: Yo | S9: 46266 | V9: Día 1

Sheet 04_REUNIONES
A1: 04 — SISTEMA DE REUNIONES / CADENCIAS
A3: Meeting ID | B3: Activa | C3: Nombre | D3: Cadencia | E3: Regla día | F3: Hora | G3: Duración min | H3: Propósito | I3: Decisión/Salida obligatoria | J3: Owner | K3: Participantes | L3: Pre-read | M3: Agenda/Link | N3: OKR/KPI | O3: Próxima fecha | P3: Última fecha | Q3: Efectividad 1-5 | R3: Acciones generadas | S3: WA reminder | T3: Calendar | U3: Notas
A4: MT-001 | B4: No | C4: Daily de operación | D4: DIARIA | E4: LABORABLES | F4: 0.33333333 | G4: 15 | H4: Alinear bloqueos y prioridades | I4: 3 prioridades + bloqueos + responsables | J4: Yo | K4: Equipo | S4: Sí | T4: Sí | U4: Activar solo si agrega valor
A5: MT-002 | B5: No | C5: Weekly de resultados | D5: SEMANAL | E5: VIE | F5: 0.64583333 | G5: 45 | H5: Revisar resultados y decisiones | I5: Decisiones, owners y fechas | J5: Yo | K5: Equipo | S5: Sí | T5: Sí
A6: MT-003 | B6: No | C6: 1:1 | D6: SEMANAL | E6: MAR | F6: 0.58333333 | G6: 30 | H6: Coaching y desbloqueo | I6: 1 compromiso concreto | J6: Yo | K6: Colaborador | S6: Sí | T6: Sí
A7: MT-004 | B7: No | C7: Revisión estratégica mensual | D7: MENSUAL | E7: 1 | F7: 0.375 | G7: 60 | H7: Revisar OKR, riesgos y recursos | I7: Cambios de prioridad aprobados | J7: Yo | K7: Equipo clave | S7: Sí | T7: Sí

Sheet 05_OKR
A1: 05 — OBJETIVOS / OKR / RESULTADOS CLAVE
A3: OKR ID | B3: Objetivo | C3: Resultado clave | D3: Responsable | E3: Periodo | F3: Línea base | G3: Meta | H3: Actual | I3: Unidad | J3: Progreso % | K3: Confianza 1-5 | L3: Fecha límite | M3: Prioridad | N3: Estado | O3: Última actualización | P3: Próxima acción | Q3: Notas
A4: OKR-001 | B4: Ejemplo: elevar ejecución personal | C4: Completar ≥85% de compromisos planificados | D4: Yo | E4: Q3 2026 | F4: 0.6 | G4: 0.85 | H4: 0.7 | I4: % | J4: =IF(A4="","",IFERROR(IF(I4="%",H4/G4,IF(G4=F4,0,(H4-F4)/(G4-F4))),0)) -> 0.82352941 | K4: 4 | L4: 46295 | M4: P1 | N4: En curso | O4: 46255 | P4: Cerrar Top 3 diario | Q4: Reemplazar
A5: OKR-002 | B5: Ejemplo: proteger concentración | C5: Lograr ≥600 min de foco profundo/semana | D5: Yo | E5: Q3 2026 | F5: 300 | G5: 600 | H5: 420 | I5: min/sem | J5: =IF(A5="","",IFERROR(IF(I5="%",H5/G5,IF(G5=F5,0,(H5-F5)/(G5-F5))),0)) -> 0.4 | K5: 3 | L5: 46295 | M5: P1 | N5: En curso | O5: 46255 | P5: Blindar bloques AM
J6: =IF(A6="","",IFERROR(IF(I6="%",H6/G6,IF(G6=F6,0,(H6-F6)/(G6-F6))),0))
J7: =IF(A7="","",IFERROR(IF(I7="%",H7/G7,IF(G7=F7,0,(H7-F7)/(G7-F7))),0))
J8: =IF(A8="","",IFERROR(IF(I8="%",H8/G8,IF(G8=F8,0,(H8-F8)/(G8-F8))),0))
J9: =IF(A9="","",IFERROR(IF(I9="%",H9/G9,IF(G9=F9,0,(H9-F9)/(G9-F9))),0))
J10: =IF(A10="","",IFERROR(IF(I10="%",H10/G10,IF(G10=F10,0,(H10-F10)/(G10-F10))),0))
J11: =IF(A11="","",IFERROR(IF(I11="%",H11/G11,IF(G11=F11,0,(H11-F11)/(G11-F11))),0))
J12: =IF(A12="","",IFERROR(IF(I12="%",H12/G12,IF(G12=F12,0,(H12-F12)/(G12-F12))),0))
J13: =IF(A13="","",IFERROR(IF(I13="%",H13/G13,IF(G13=F13,0,(H13-F13)/(G13-F13))),0))
J14: =IF(A14="","",IFERROR(IF(I14="%",H14/G14,IF(G14=F14,0,(H14-F14)/(G14-F14))),0))
J15: =IF(A15="","",IFERROR(IF(I15="%",H15/G15,IF(G15=F15,0,(H15-F15)/(G15-F15))),0))
J16: =IF(A16="","",IFERROR(IF(I16="%",H16/G16,IF(G16=F16,0,(H16-F16)/(G16-F16))),0))
J17: =IF(A17="","",IFERROR(IF(I17="%",H17/G17,IF(G17=F17,0,(H17-F17)/(G17-F17))),0))
... J300: =IF(A300="","",IFERROR(IF(I300="%",H300/G300,IF(G300=F300,0,(H300-F300)/(G300-F300))),0))

Sheet 06_METRICAS_DIARIAS
A1: 06 — MÉTRICAS DIARIAS / HIGIENE DE EJECUCIÓN
A3: Fecha | B3: Min foco plan | C3: Min foco real | D3: Interrupciones >2min | E3: Min reuniones | F3: Min agenda plan | G3: Min agenda hecho | H3: Plan diario | I3: Cierre diario | J3: Revisión semanal | K3: Energía AM 1-5 | L3: Energía PM 1-5 | M3: Mejora 1% | N3: Comentarios
A4: 46225 | B4: =SUMIFS('02_AGENDA'!$W$4:$W$500,'02_AGENDA'!$B$4:$B$500,$A4,'02_AGENDA'!$Z$4:$Z$500,"Sí") -> 0 | C4: =SUMIFS('02_AGENDA'!$X$4:$X$500,'02_AGENDA'!$B$4:$B$500,$A4,'02_AGENDA'!$Z$4:$Z$500,"Sí") -> 0 | E4: =SUMIFS('02_AGENDA'!$W$4:$W$500,'02_AGENDA'!$B$4:$B$500,$A4,'02_AGENDA'!$E$4:$E$500,"Reunión") -> 0 | F4: =SUMIFS('02_AGENDA'!$W$4:$W$500,'02_AGENDA'!$B$4:$B$500,$A4) -> 0 | G4: =SUMIFS('02_AGENDA'!$X$4:$X$500,'02_AGENDA'!$B$4:$B$500,$A4,'02_AGENDA'!$M$4:$M$500,"Hecho") -> 0
A5: 46226 | B5: =SUMIFS('02_AGENDA'!$W$4:$W$500,'02_AGENDA'!$B$4:$B$500,$A5,'02_AGENDA'!$Z$4:$Z$500,"Sí") -> 0 | C5: =SUMIFS('02_AGENDA'!$X$4:$X$500,'02_AGENDA'!$B$4:$B$500,$A5,'02_AGENDA'!$Z$4:$Z$500,"Sí") -> 0 | E5: =SUMIFS('02_AGENDA'!$W$4:$W$500,'02_AGENDA'!$B$4:$B$500,$A5,'02_AGENDA'!$E$4:$E$500,"Reunión") -> 0 | F5: =SUMIFS('02_AGENDA'!$W$4:$W$500,'02_AGENDA'!$B$4:$B$500,$A5) -> 0 | G5: =SUMIFS('02_AGENDA'!$X$4:$X$500,'02_AGENDA'!$B$4:$B$500,$A5,'02_AGENDA'!$M$4:$M$500,"Hecho") -> 0
A6: 46227 | B6: =SUMIFS('02_AGENDA'!$W$4:$W$500,'02_AGENDA'!$B$4:$B$500,$A6,'02_AGENDA'!$Z$4:$Z$500,"Sí") -> 0 | C6: =SUMIFS('02_AGENDA'!$X$4:$X$500,'02_AGENDA'!$B$4:$B$500,$A6,'02_AGENDA'!$Z$4:$Z$500,"Sí") -> 0 | E6: =SUMIFS('02_AGENDA'!$W$4:$W$500,'02_AGENDA'!$B$4:$B$500,$A6,'02_AGENDA'!$E$4:$E$500,"Reunión") -> 0 | F6: =SUMIFS('02_AGENDA'!$W$4:$W$500,'02_AGENDA'!$B$4:$B$500,$A6) -> 0 | G6: =SUMIFS('02_AGENDA'!$X$4:$X$500,'02_AGENDA'!$B$4:$B$500,$A6,'02_AGENDA'!$M$4:$M$500,"Hecho") -> 0
A7: 46228 | B7: =SUMIFS('02_AGENDA'!$W$4:$W$500,'02_AGENDA'!$B$4:$B$500,$A7,'02_AGENDA'!$Z$4:$Z$500,"Sí") -> 0 | C7: =SUMIFS('02_AGENDA'!$X$4:$X$500,'02_AGENDA'!$B$4:$B$500,$A7,'02_AGENDA'!$Z$4:$Z$500,"Sí") -> 0 | E7: =SUMIFS('02_AGENDA'!$W$4:$W$500,'02_AGENDA'!$B$4:$B$500,$A7,'02_AGENDA'!$E$4:$E$500,"Reunión") -> 0 | F7: =SUMIFS('02_AGENDA'!$W$4:$W$500,'02_AGENDA'!$B$4:$B$500,$A7) -> 0 | G7: =SUMIFS('02_AGENDA'!$X$4:$X$500,'02_AGENDA'!$B$4:$B$500,$A7,'02_AGENDA'!$M$4:$M$500,"Hecho") -> 0
A8: 46229 | B8: =SUMIFS('02_AGENDA'!$W$4:$W$500,'02_AGENDA'!$B$4:$B$500,$A8,'02_AGENDA'!$Z$4:$Z$500,"Sí") -> 0 | C8: =SUMIFS('02_AGENDA'!$X$4:$X$500,'02_AGENDA'!$B$4:$B$500,$A8,'02_AGENDA'!$Z$4:$Z$500,"Sí") -> 0 | E8: =SUMIFS('02_AGENDA'!$W$4:$W$500,'02_AGENDA'!$B$4:$B$500,$A8,'02_AGENDA'!$E$4:$E$500,"Reunión") -> 0 | F8: =SUMIFS('02_AGENDA'!$W$4:$W$500,'02_AGENDA'!$B$4:$B$500,$A8) -> 0 | G8: =SUMIFS('02_AGENDA'!$X$4:$X$500,'02_AGENDA'!$B$4:$B$500,$A8,'02_AGENDA'!$M$4:$M$500,"Hecho") -> 0
A9: 46230 | B9: =SUMIFS('02_AGENDA'!$W$4:$W$500,'02_AGENDA'!$B$4:$B$500,$A9,'02_AGENDA'!$Z$4:$Z$500,"Sí") -> 0 | C9: =SUMIFS('02_AGENDA'!$X$4:$X$500,'02_AGENDA'!$B$4:$B$500,$A9,'02_AGENDA'!$Z$4:$Z$500,"Sí") -> 0 | E9: =SUMIFS('02_AGENDA'!$W$4:$W$500,'02_AGENDA'!$B$4:$B$500,$A9,'02_AGENDA'!$E$4:$E$500,"Reunión") -> 0 | F9: =SUMIFS('02_AGENDA'!$W$4:$W$500,'02_AGENDA'!$B$4:$B$500,$A9) -> 0 | G9: =SUMIFS('02_AGENDA'!$X$4:$X$500,'02_AGENDA'!$B$4:$B$500,$A9,'02_AGENDA'!$M$4:$M$500,"Hecho") -> 0
A10: 46231 | B10: =SUMIFS('02_AGENDA'!$W$4:$W$500,'02_AGENDA'!$B$4:$B$500,$A10,'02_AGENDA'!$Z$4:$Z$500,"Sí") -> 0 | C10: =SUMIFS('02_AGENDA'!$X$4:$X$500,'02_AGENDA'!$B$4:$B$500,$A10,'02_AGENDA'!$Z$4:$Z$500,"Sí") -> 0 | E10: =SUMIFS('02_AGENDA'!$W$4:$W$500,'02_AGENDA'!$B$4:$B$500,$A10,'02_AGENDA'!$E$4:$E$500,"Reunión") -> 0 | F10: =SUMIFS('02_AGENDA'!$W$4:$W$500,'02_AGENDA'!$B$4:$B$500,$A10) -> 0 | G10: =SUMIFS('02_AGENDA'!$X$4:$X$500,'02_AGENDA'!$B$4:$B$500,$A10,'02_AGENDA'!$M$4:$M$500,"Hecho") -> 0
A11: 46232 | B11: =SUMIFS('02_AGENDA'!$W$4:$W$500,'02_AGENDA'!$B$4:$B$500,$A11,'02_AGENDA'!$Z$4:$Z$500,"Sí") -> 0 | C11: =SUMIFS('02_AGENDA'!$X$4:$X$500,'02_AGENDA'!$B$4:$B$500,$A11,'02_AGENDA'!$Z$4:$Z$500,"Sí") -> 0 | E11: =SUMIFS('02_AGENDA'!$W$4:$W$500,'02_AGENDA'!$B$4:$B$500,$A11,'02_AGENDA'!$E$4:$E$500,"Reunión") -> 0 | F11: =SUMIFS('02_AGENDA'!$W$4:$W$500,'02_AGENDA'!$B$4:$B$500,$A11) -> 0 | G11: =SUMIFS('02_AGENDA'!$X$4:$X$500,'02_AGENDA'!$B$4:$B$500,$A11,'02_AGENDA'!$M$4:$M$500,"Hecho") -> 0
A12: 46233 | B12: =SUMIFS('02_AGENDA'!$W$4:$W$500,'02_AGENDA'!$B$4:$B$500,$A12,'02_AGENDA'!$Z$4:$Z$500,"Sí") -> 0 | C12: =SUMIFS('02_AGENDA'!$X$4:$X$500,'02_AGENDA'!$B$4:$B$500,$A12,'02_AGENDA'!$Z$4:$Z$500,"Sí") -> 0 | E12: =SUMIFS('02_AGENDA'!$W$4:$W$500,'02_AGENDA'!$B$4:$B$500,$A12,'02_AGENDA'!$E$4:$E$500,"Reunión") -> 0 | F12: =SUMIFS('02_AGENDA'!$W$4:$W$500,'02_AGENDA'!$B$4:$B$500,$A12) -> 0 | G12: =SUMIFS('02_AGENDA'!$X$4:$X$500,'02_AGENDA'!$B$4:$B$500,$A12,'02_AGENDA'!$M$4:$M$500,"Hecho") -> 0
A13: 46234 | B13: =SUMIFS('02_AGENDA'!$W$4:$W$500,'02_AGENDA'!$B$4:$B$500,$A13,'02_AGENDA'!$Z$4:$Z$500,"Sí") -> 0 | C13: =SUMIFS('02_AGENDA'!$X$4:$X$500,'02_AGENDA'!$B$4:$B$500,$A13,'02_AGENDA'!$Z$4:$Z$500,"Sí") -> 0 | E13: =SUMIFS('02_AGENDA'!$W$4:$W$500,'02_AGENDA'!$B$4:$B$500,$A13,'02_AGENDA'!$E$4:$E$500,"Reunión") -> 0 | F13: =SUMIFS('02_AGENDA'!$W$4:$W$500,'02_AGENDA'!$B$4:$B$500,$A13) -> 0 | G13: =SUMIFS('02_AGENDA'!$X$4:$X$500,'02_AGENDA'!$B$4:$B$500,$A13,'02_AGENDA'!$M$4:$M$500,"Hecho") -> 0
A14: 46235 | B14: =SUMIFS('02_AGENDA'!$W$4:$W$500,'02_AGENDA'!$B$4:$B$500,$A14,'02_AGENDA'!$Z$4:$Z$500,"Sí") -> 0 | C14: =SUMIFS('02_AGENDA'!$X$4:$X$500,'02_AGENDA'!$B$4:$B$500,$A14,'02_AGENDA'!$Z$4:$Z$500,"Sí") -> 0 | E14: =SUMIFS('02_AGENDA'!$W$4:$W$500,'02_AGENDA'!$B$4:$B$500,$A14,'02_AGENDA'!$E$4:$E$500,"Reunión") -> 0 | F14: =SUMIFS('02_AGENDA'!$W$4:$W$500,'02_AGENDA'!$B$4:$B$500,$A14) -> 0 | G14: =SUMIFS('02_AGENDA'!$X$4:$X$500,'02_AGENDA'!$B$4:$B$500,$A14,'02_AGENDA'!$M$4:$M$500,"Hecho") -> 0
A15: 46236 | B15: =SUMIFS('02_AGENDA'!$W$4:$W$500,'02_AGENDA'!$B$4:$B$500,$A15,'02_AGENDA'!$Z$4:$Z$500,"Sí") -> 0 | C15: =SUMIFS('02_AGENDA'!$X$4:$X$500,'02_AGENDA'!$B$4:$B$500,$A15,'02_AGENDA'!$Z$4:$Z$500,"Sí") -> 0 | E15: =SUMIFS('02_AGENDA'!$W$4:$W$500,'02_AGENDA'!$B$4:$B$500,$A15,'02_AGENDA'!$E$4:$E$500,"Reunión") -> 0 | F15: =SUMIFS('02_AGENDA'!$W$4:$W$500,'02_AGENDA'!$B$4:$B$500,$A15) -> 0 | G15: =SUMIFS('02_AGENDA'!$X$4:$X$500,'02_AGENDA'!$B$4:$B$500,$A15,'02_AGENDA'!$M$4:$M$500,"Hecho") -> 0
... A94: 46315 | B94: =SUMIFS('02_AGENDA'!$W$4:$W$500,'02_AGENDA'!$B$4:$B$500,$A94,'02_AGENDA'!$Z$4:$Z$500,"Sí") -> 0 | C94: =SUMIFS('02_AGENDA'!$X$4:$X$500,'02_AGENDA'!$B$4:$B$500,$A94,'02_AGENDA'!$Z$4:$Z$500,"Sí") -> 0 | E94: =SUMIFS('02_AGENDA'!$W$4:$W$500,'02_AGENDA'!$B$4:$B$500,$A94,'02_AGENDA'!$E$4:$E$500,"Reunión") -> 0 | F94: =SUMIFS('02_AGENDA'!$W$4:$W$500,'02_AGENDA'!$B$4:$B$500,$A94) -> 0 | G94: =SUMIFS('02_AGENDA'!$X$4:$X$500,'02_AGENDA'!$B$4:$B$500,$A94,'02_AGENDA'!$M$4:$M$500,"Hecho") -> 0

Sheet 07_REPORTES
A1: 07 — REPORTES AUTOMÁTICOS
A3: REPORTE SEMANAL ACTUAL
A4: Métrica | B4: Valor | C4: Meta P95 | D4: Estado | E4: Interpretación
A5: Inicio semana | B5: =TODAY()-WEEKDAY(TODAY(),2)+1 -> 46265
A6: Fin semana | B6: =B5+6 -> 46271
A7: Ejecución completada | B7: =IFERROR(COUNTIFS('02_AGENDA'!$B$4:$B$500,">="&$B$5,'02_AGENDA'!$B$4:$B$500,"<="&$B$6,'02_AGENDA'!$M$4:$M$500,"Hecho")/COUNTIFS('02_AGENDA'!$B$4:$B$500,">="&$B$5,'02_AGENDA'!$B$4:$B$500,"<="&$B$6,'02_AGENDA'!$A$4:$A$500,"<>"),0) -> 0 | C7: 0.85 | D7: =IF(B7>=C7,"OK","MEJORAR") -> MEJORAR | E7: Compromisos cerrados / compromisos planificados
A8: Foco profundo (min) | B8: =SUMIFS('02_AGENDA'!$X$4:$X$500,'02_AGENDA'!$B$4:$B$500,">="&$B$5,'02_AGENDA'!$B$4:$B$500,"<="&$B$6,'02_AGENDA'!$Z$4:$Z$500,"Sí") -> 0 | C8: 600 | D8: =IF(B8>=C8,"OK","MEJORAR") -> MEJORAR | E8: 10 h/semana como estándar configurable
A9: Vencidas abiertas | B9: =COUNTIFS('02_AGENDA'!$U$4:$U$500,"<"&TODAY(),'02_AGENDA'!$M$4:$M$500,"<>Hecho",'02_AGENDA'!$M$4:$M$500,"<>Cancelada",'02_AGENDA'!$A$4:$A$500,"<>") -> 3 | C9: 2 | D9: =IF(B9<=C9,"OK","MEJORAR") -> MEJORAR | E9: Backlog crítico
A10: Reuniones (min) | B10: =SUMIFS('02_AGENDA'!$W$4:$W$500,'02_AGENDA'!$B$4:$B$500,">="&$B$5,'02_AGENDA'!$B$4:$B$500,"<="&$B$6,'02_AGENDA'!$E$4:$E$500,"Reunión") -> 0 | C10: 480 | D10: =IF(B10<=C10,"OK","REVISAR") -> OK | E10: Controlar carga de reuniones
A11: OKR progreso promedio | B11: =IFERROR(AVERAGE('05_OKR'!$J$4:$J$300),0) -> 0.61176471 | C11: 0.7 | D11: =IF(B11>=C11,"OK","MEJORAR") -> MEJORAR | E11: Avance de resultados clave
A14: REPORTE MENSUAL ACTUAL
A15: Métrica | B15: Valor | C15: Meta | D15: Estado | E15: Interpretación
A16: Inicio mes | B16: =EOMONTH(TODAY(),-1)+1 -> 46266
A17: Fin mes | B17: =EOMONTH(TODAY(),0) -> 46295
A18: % actividades hechas | B18: =IFERROR(COUNTIFS('02_AGENDA'!$B$4:$B$500,">="&$B$16,'02_AGENDA'!$B$4:$B$500,"<="&$B$17,'02_AGENDA'!$M$4:$M$500,"Hecho")/COUNTIFS('02_AGENDA'!$B$4:$B$500,">="&$B$16,'02_AGENDA'!$B$4:$B$500,"<="&$B$17,'02_AGENDA'!$A$4:$A$500,"<>"),0) -> 0 | C18: 0.85 | D18: =IF(B18>=C18,"OK","MEJORAR") -> MEJORAR | E18: Consistencia mensual
A19: Foco profundo (min) | B19: =SUMIFS('02_AGENDA'!$X$4:$X$500,'02_AGENDA'!$B$4:$B$500,">="&$B$16,'02_AGENDA'!$B$4:$B$500,"<="&$B$17,'02_AGENDA'!$Z$4:$Z$500,"Sí") -> 0 | C19: 2400 | D19: =IF(B19>=C19,"OK","MEJORAR") -> MEJORAR | E19: 40 h/mes configurable
A20: Promedio efectividad reuniones | B20: =IFERROR(AVERAGE('04_REUNIONES'!$Q$4:$Q$200),0) -> 0 | C20: 4 | D20: =IF(B20>=C20,"OK","MEJORAR") -> MEJORAR | E20: Escala 1-5
A21: Progreso OKR promedio | B21: =IFERROR(AVERAGE('05_OKR'!$J$4:$J$300),0) -> 0.61176471 | C21: 0.7 | D21: =IF(B21>=C21,"OK","MEJORAR") -> MEJORAR | E21: Resultado, no actividad

Sheet 08_DASHBOARD
A1: 08 — DASHBOARD P95 / CONTROL EJECUTIVO
A3: ÍNDICE P95 (interno) | D3: EJECUCIÓN HOY | G3: FOCO HOY (MIN) | J3: VENCIDAS ABIERTAS | M3: EFECT. REUNIONES
A4: =ROUND(MIN(1,$D$4/'12_CONFIG'!$B$4)*'12_CONFIG'!$C$4*100+MIN(1,$G$4/'12_CONFIG'!$B$5)*'12_CONFIG'!$C$5*100+MIN(1,MAX(0,1-$J$4/MAX(1,'12_CONFIG'!$B$6)))*'12_CONFIG'!$C$6*100+MIN(1,$M$4/'12_CONFIG'!$B$7)*'12_CONFIG'!$C$7*100+MIN(1,$A$9/'12_CONFIG'!$B$8)*'12_CONFIG'!$C$8*100+MIN(1,$C$9/'12_CONFIG'!$B$9)*'12_CONFIG'!$C$9*100+MIN(1,$E$9/'12_CONFIG'!$B$10)*'12_CONFIG'!$C$10*100,1) -> 13.1 | D4: =IFERROR(COUNTIFS('02_AGENDA'!$B$4:$B$500,TODAY(),'02_AGENDA'!$M$4:$M$500,"Hecho")/COUNTIFS('02_AGENDA'!$B$4:$B$500,TODAY(),'02_AGENDA'!$A$4:$A$500,"<>"),0) -> 0 | G4: =SUMIFS('02_AGENDA'!$X$4:$X$500,'02_AGENDA'!$B$4:$B$500,TODAY(),'02_AGENDA'!$Z$4:$Z$500,"Sí") -> 0 | J4: =COUNTIFS('02_AGENDA'!$U$4:$U$500,"<"&TODAY(),'02_AGENDA'!$M$4:$M$500,"<>Hecho",'02_AGENDA'!$M$4:$M$500,"<>Cancelada",'02_AGENDA'!$A$4:$A$500,"<>") -> 3 | M4: =IFERROR(AVERAGE('04_REUNIONES'!$Q$4:$Q$200),0) -> 0
A8: OKR progreso | C8: Ejecución semanal | E8: Revisión semanal | G8: Interrupciones hoy
A9: =IFERROR(AVERAGE('05_OKR'!$J$4:$J$300),0) -> 0.61176471 | B9: =IFERROR(AVERAGE('05_OKR'!$J$4:$J$300),0) -> 0.61176471 | C9: =IFERROR('07_REPORTES'!B7,0) -> 0 | E9: =IF(COUNTIFS('06_METRICAS_DIARIAS'!$A$4:$A$94,">="&'07_REPORTES'!$B$5,'06_METRICAS_DIARIAS'!$A$4:$A$94,"<="&'07_REPORTES'!$B$6,'06_METRICAS_DIARIAS'!$J$4:$J$94,"Sí")>0,1,0) -> 0 | G9: =IFERROR(SUMIFS('06_METRICAS_DIARIAS'!$D$4:$D$94,'06_METRICAS_DIARIAS'!$A$4:$A$94,TODAY()),0) -> 0 | H9: =IF(COUNTIFS('06_METRICAS_DIARIAS'!$A$4:$A$94,">="&'07_REPORTES'!$B$5,'06_METRICAS_DIARIAS'!$A$4:$A$94,"<="&'07_REPORTES'!$B$6,'06_METRICAS_DIARIAS'!$J$4:$J$94,"Sí")>0,1,0) -> 0
A12: TENDENCIA — ÚLTIMOS 14 DÍAS
A13: Fecha | B13: Foco real | C13: Agenda plan | D13: Agenda hecho | E13: Ejecución % | F13: Interrupciones
A14: 46242 | B14: =IFERROR(_xludf.XLOOKUP(A14,'06_METRICAS_DIARIAS'!$A:$A,'06_METRICAS_DIARIAS'!$C:$C,0),0) -> 0 | C14: =IFERROR(_xludf.XLOOKUP(A14,'06_METRICAS_DIARIAS'!$A:$A,'06_METRICAS_DIARIAS'!$F:$F,0),0) -> 0 | D14: =IFERROR(_xludf.XLOOKUP(A14,'06_METRICAS_DIARIAS'!$A:$A,'06_METRICAS_DIARIAS'!$G:$G,0),0) -> 0 | E14: =IFERROR(D14/C14,0) -> 0 | F14: =IFERROR(_xludf.XLOOKUP(A14,'06_METRICAS_DIARIAS'!$A:$A,'06_METRICAS_DIARIAS'!$D:$D,0),0) -> 0
A15: 46243 | B15: =IFERROR(_xludf.XLOOKUP(A15,'06_METRICAS_DIARIAS'!$A:$A,'06_METRICAS_DIARIAS'!$C:$C,0),0) -> 0 | C15: =IFERROR(_xludf.XLOOKUP(A15,'06_METRICAS_DIARIAS'!$A:$A,'06_METRICAS_DIARIAS'!$F:$F,0),0) -> 0 | D15: =IFERROR(_xludf.XLOOKUP(A15,'06_METRICAS_DIARIAS'!$A:$A,'06_METRICAS_DIARIAS'!$G:$G,0),0) -> 0 | E15: =IFERROR(D15/C15,0) -> 0 | F15: =IFERROR(_xludf.XLOOKUP(A15,'06_METRICAS_DIARIAS'!$A:$A,'06_METRICAS_DIARIAS'!$D:$D,0),0) -> 0
A16: 46244 | B16: =IFERROR(_xludf.XLOOKUP(A16,'06_METRICAS_DIARIAS'!$A:$A,'06_METRICAS_DIARIAS'!$C:$C,0),0) -> 0 | C16: =IFERROR(_xludf.XLOOKUP(A16,'06_METRICAS_DIARIAS'!$A:$A,'06_METRICAS_DIARIAS'!$F:$F,0),0) -> 0 | D16: =IFERROR(_xludf.XLOOKUP(A16,'06_METRICAS_DIARIAS'!$A:$A,'06_METRICAS_DIARIAS'!$G:$G,0),0) -> 0 | E16: =IFERROR(D16/C16,0) -> 0 | F16: =IFERROR(_xludf.XLOOKUP(A16,'06_METRICAS_DIARIAS'!$A:$A,'06_METRICAS_DIARIAS'!$D:$D,0),0) -> 0
A17: 46245 | B17: =IFERROR(_xludf.XLOOKUP(A17,'06_METRICAS_DIARIAS'!$A:$A,'06_METRICAS_DIARIAS'!$C:$C,0),0) -> 0 | C17: =IFERROR(_xludf.XLOOKUP(A17,'06_METRICAS_DIARIAS'!$A:$A,'06_METRICAS_DIARIAS'!$F:$F,0),0) -> 0 | D17: =IFERROR(_xludf.XLOOKUP(A17,'06_METRICAS_DIARIAS'!$A:$A,'06_METRICAS_DIARIAS'!$G:$G,0),0) -> 0 | E17: =IFERROR(D17/C17,0) -> 0 | F17: =IFERROR(_xludf.XLOOKUP(A17,'06_METRICAS_DIARIAS'!$A:$A,'06_METRICAS_DIARIAS'!$D:$D,0),0) -> 0
A18: 46246 | B18: =IFERROR(_xludf.XLOOKUP(A18,'06_METRICAS_DIARIAS'!$A:$A,'06_METRICAS_DIARIAS'!$C:$C,0),0) -> 0 | C18: =IFERROR(_xludf.XLOOKUP(A18,'06_METRICAS_DIARIAS'!$A:$A,'06_METRICAS_DIARIAS'!$F:$F,0),0) -> 0 | D18: =IFERROR(_xludf.XLOOKUP(A18,'06_METRICAS_DIARIAS'!$A:$A,'06_METRICAS_DIARIAS'!$G:$G,0),0) -> 0 | E18: =IFERROR(D18/C18,0) -> 0 | F18: =IFERROR(_xludf.XLOOKUP(A18,'06_METRICAS_DIARIAS'!$A:$A,'06_METRICAS_DIARIAS'!$D:$D,0),0) -> 0
A19: 46247 | B19: =IFERROR(_xludf.XLOOKUP(A19,'06_METRICAS_DIARIAS'!$A:$A,'06_METRICAS_DIARIAS'!$C:$C,0),0) -> 0 | C19: =IFERROR(_xludf.XLOOKUP(A19,'06_METRICAS_DIARIAS'!$A:$A,'06_METRICAS_DIARIAS'!$F:$F,0),0) -> 0 | D19: =IFERROR(_xludf.XLOOKUP(A19,'06_METRICAS_DIARIAS'!$A:$A,'06_METRICAS_DIARIAS'!$G:$G,0),0) -> 0 | E19: =IFERROR(D19/C19,0) -> 0 | F19: =IFERROR(_xludf.XLOOKUP(A19,'06_METRICAS_DIARIAS'!$A:$A,'06_METRICAS_DIARIAS'!$D:$D,0),0) -> 0
A20: 46248 | B20: =IFERROR(_xludf.XLOOKUP(A20,'06_METRICAS_DIARIAS'!$A:$A,'06_METRICAS_DIARIAS'!$C:$C,0),0) -> 0 | C20: =IFERROR(_xludf.XLOOKUP(A20,'06_METRICAS_DIARIAS'!$A:$A,'06_METRICAS_DIARIAS'!$F:$F,0),0) -> 0 | D20: =IFERROR(_xludf.XLOOKUP(A20,'06_METRICAS_DIARIAS'!$A:$A,'06_METRICAS_DIARIAS'!$G:$G,0),0) -> 0 | E20: =IFERROR(D20/C20,0) -> 0 | F20: =IFERROR(_xludf.XLOOKUP(A20,'06_METRICAS_DIARIAS'!$A:$A,'06_METRICAS_DIARIAS'!$D:$D,0),0) -> 0
A21: 46249 | B21: =IFERROR(_xludf.XLOOKUP(A21,'06_METRICAS_DIARIAS'!$A:$A,'06_METRICAS_DIARIAS'!$C:$C,0),0) -> 0 | C21: =IFERROR(_xludf.XLOOKUP(A21,'06_METRICAS_DIARIAS'!$A:$A,'06_METRICAS_DIARIAS'!$F:$F,0),0) -> 0 | D21: =IFERROR(_xludf.XLOOKUP(A21,'06_METRICAS_DIARIAS'!$A:$A,'06_METRICAS_DIARIAS'!$G:$G,0),0) -> 0 | E21: =IFERROR(D21/C21,0) -> 0 | F21: =IFERROR(_xludf.XLOOKUP(A21,'06_METRICAS_DIARIAS'!$A:$A,'06_METRICAS_DIARIAS'!$D:$D,0),0) -> 0
A22: 46250 | B22: =IFERROR(_xludf.XLOOKUP(A22,'06_METRICAS_DIARIAS'!$A:$A,'06_METRICAS_DIARIAS'!$C:$C,0),0) -> 0 | C22: =IFERROR(_xludf.XLOOKUP(A22,'06_METRICAS_DIARIAS'!$A:$A,'06_METRICAS_DIARIAS'!$F:$F,0),0) -> 0 | D22: =IFERROR(_xludf.XLOOKUP(A22,'06_METRICAS_DIARIAS'!$A:$A,'06_METRICAS_DIARIAS'!$G:$G,0),0) -> 0 | E22: =IFERROR(D22/C22,0) -> 0 | F22: =IFERROR(_xludf.XLOOKUP(A22,'06_METRICAS_DIARIAS'!$A:$A,'06_METRICAS_DIARIAS'!$D:$D,0),0) -> 0
A23: 46251 | B23: =IFERROR(_xludf.XLOOKUP(A23,'06_METRICAS_DIARIAS'!$A:$A,'06_METRICAS_DIARIAS'!$C:$C,0),0) -> 0 | C23: =IFERROR(_xludf.XLOOKUP(A23,'06_METRICAS_DIARIAS'!$A:$A,'06_METRICAS_DIARIAS'!$F:$F,0),0) -> 0 | D23: =IFERROR(_xludf.XLOOKUP(A23,'06_METRICAS_DIARIAS'!$A:$A,'06_METRICAS_DIARIAS'!$G:$G,0),0) -> 0 | E23: =IFERROR(D23/C23,0) -> 0 | F23: =IFERROR(_xludf.XLOOKUP(A23,'06_METRICAS_DIARIAS'!$A:$A,'06_METRICAS_DIARIAS'!$D:$D,0),0) -> 0
A24: 46252 | B24: =IFERROR(_xludf.XLOOKUP(A24,'06_METRICAS_DIARIAS'!$A:$A,'06_METRICAS_DIARIAS'!$C:$C,0),0) -> 0 | C24: =IFERROR(_xludf.XLOOKUP(A24,'06_METRICAS_DIARIAS'!$A:$A,'06_METRICAS_DIARIAS'!$F:$F,0),0) -> 0 | D24: =IFERROR(_xludf.XLOOKUP(A24,'06_METRICAS_DIARIAS'!$A:$A,'06_METRICAS_DIARIAS'!$G:$G,0),0) -> 0 | E24: =IFERROR(D24/C24,0) -> 0 | F24: =IFERROR(_xludf.XLOOKUP(A24,'06_METRICAS_DIARIAS'!$A:$A,'06_METRICAS_DIARIAS'!$D:$D,0),0) -> 0
A25: 46253 | B25: =IFERROR(_xludf.XLOOKUP(A25,'06_METRICAS_DIARIAS'!$A:$A,'06_METRICAS_DIARIAS'!$C:$C,0),0) -> 0 | C25: =IFERROR(_xludf.XLOOKUP(A25,'06_METRICAS_DIARIAS'!$A:$A,'06_METRICAS_DIARIAS'!$F:$F,0),0) -> 0 | D25: =IFERROR(_xludf.XLOOKUP(A25,'06_METRICAS_DIARIAS'!$A:$A,'06_METRICAS_DIARIAS'!$G:$G,0),0) -> 0 | E25: =IFERROR(D25/C25,0) -> 0 | F25: =IFERROR(_xludf.XLOOKUP(A25,'06_METRICAS_DIARIAS'!$A:$A,'06_METRICAS_DIARIAS'!$D:$D,0),0) -> 0
... A27: 46255 | B27: =IFERROR(_xludf.XLOOKUP(A27,'06_METRICAS_DIARIAS'!$A:$A,'06_METRICAS_DIARIAS'!$C:$C,0),0) -> 0 | C27: =IFERROR(_xludf.XLOOKUP(A27,'06_METRICAS_DIARIAS'!$A:$A,'06_METRICAS_DIARIAS'!$F:$F,0),0) -> 0 | D27: =IFERROR(_xludf.XLOOKUP(A27,'06_METRICAS_DIARIAS'!$A:$A,'06_METRICAS_DIARIAS'!$G:$G,0),0) -> 0 | E27: =IFERROR(D27/C27,0) -> 0 | F27: =IFERROR(_xludf.XLOOKUP(A27,'06_METRICAS_DIARIAS'!$A:$A,'06_METRICAS_DIARIAS'!$D:$D,0),0) -> 0

Sheet 09_MOBILE
A1: 09 — CELULAR COMO EXTENSIÓN DEL ASISTENTE
A3: El teléfono se usa como terminal de captura y decisión, no como fuente adicional de ruido. El asistente empuja solo eventos críticos y opera con comandos cortos.
A6: PROTOCOLO MÓVIL P95
A7: Momento | B7: Intervención del asistente | C7: Respuesta ideal | D7: Métrica
A8: 06:30 | B8: Brief: Top 3, reuniones, vencimientos, foco protegido | C8: Confirmar / ajustar | D8: Plan diario
A9: 10 min antes | B9: Alerta solo P1 / reunión / fecha límite | C9: Ir / posponer / delegar | D9: Puntualidad
A10: Captura | B10: Guardar en INBOX sin procesar de inmediato | C10: CAPTURA … | D10: Cambios de contexto
A11: 12:00 | B11: Chequeo: ¿Top 1 sigue siendo el mismo? | C11: Sí / reordenar | D11: Alineación
A12: 17:30 | B12: Cierre: hechos, abiertos, bloqueados, delegados | C12: CIERRE | D12: Backlog sano
A13: Viernes | B13: Informe semanal P95 + propuesta próxima semana | C13: SEMANA | D13: Mejora continua
A15: COMANDOS
A16: Comando | B16: Función | C16: Ejemplo | D16: Salida
A17: HOY | B17: Resumen del día | C17: HOY | D17: Top 3 + agenda + vencidas
A18: CAPTURA | B18: Añadir al Inbox | C18: CAPTURA revisar contrato X | D18: Confirmación
A19: HECHO | B19: Cerrar actividad | C19: HECHO AG-0021 | D19: Estado + hora
A20: POSPONER | B20: Reprogramar minutos | C20: POSPONER AG-0021 45 | D20: Nueva hora
A21: FOCO | B21: Crear bloque inmediato | C21: FOCO 90 preparar junta | D21: Bloque + Calendar
A22: CIERRE | B22: Cierre operativo diario | C22: CIERRE | D22: Pendientes + aprendizaje
A23: SEMANA | B23: Informe semanal | C23: SEMANA | D23: KPIs + alertas
A25: REGLAS DE NOTIFICACIÓN (ANTI-RUIDO)
A26: Severidad | B26: Cuándo notificar | C26: Canal
A27: CRÍTICA | B27: P1 vencida, reunión en 10 min, bloqueo | C27: WhatsApp + Calendar
A28: ALTA | B28: Top 3 en riesgo, actividad vence hoy | C28: WhatsApp
A29: MEDIA | B29: Resumen mediodía / cierre | C29: WhatsApp agrupado
A30: BAJA | B30: Ideas, mejoras, no urgentes | C30: Sheet / reporte

Sheet 10_AUTOMATIZACION
A1: 10 — CONFIGURACIÓN DE AUTOMATIZACIÓN
A3: CONFIGURACIÓN FUNCIONAL
A4: Parámetro | B4: Valor | C4: Requerido | D4: Dónde se configura | E4: Nota
A5: TIMEZONE | B5: America/Bogota | C5: Sí | D5: Script Properties | E5: Zona horaria
A6: CALENDAR_ID | B6: primary | C6: Sí | D6: Script Properties | E6: Calendario destino
A7: WA_ENABLED | B7: FALSE | C7: No | D7: Script Properties | E7: TRUE cuando WhatsApp esté listo
A8: WA_PROVIDER | B8: META_CLOUD | C8: No | D8: Script Properties | E8: Integración incluida
A9: WA_PHONE_NUMBER_ID | C9: Sí para WA | D9: Script Properties | E9: ID de número Business
A10: WA_TOKEN | C10: Sí para WA | D10: Script Properties | E10: SECRETO: nunca en celdas
A11: WA_TO_NUMBER | C11: Sí para WA | D11: Script Properties | E11: E.164 sin +
A12: WA_API_VERSION | C12: Sí para WA | D12: Script Properties | E12: Versión vigente Graph API
A13: WA_VERIFY_TOKEN | C13: Sí inbound | D13: Script Properties | E13: Token del webhook
A14: SHEET_ID | C14: Recomendado | D14: Script Properties | E14: ID del Google Sheet
A16: TRIGGERS RECOMENDADOS
A17: Función | B17: Cadencia | C17: Hora | D17: Objetivo | E17: Tras setup | F17: Notas
A18: generateRecurringTasks | B18: Diaria | C18: 05:15 | D18: Materializar recurrencias | E18: Sí | F18: Evita duplicados
A19: dailyBrief | B19: Diaria | C19: 06:30 | D19: Brief móvil | E19: Sí | F19: WA: ventana/template
A20: upcomingAlerts | B20: Cada 15 min | C20: — | D20: Alertas críticas | E20: Sí | F20: Solo WhatsApp=Sí
A21: syncAgendaToCalendar | B21: Cada hora | C21: — | D21: Agenda → Calendar | E21: Sí | F21: Escribe Event ID
A22: weeklyReport | B22: Viernes | C22: 17:45 | D22: Reporte P95 | E22: Sí | F22: Agrupado
A24: CHECKLIST DE ACTIVACIÓN
A25: Paso | B25: Estado | C25: Acción
A26: 1 | B26: Pendiente | C26: Abrir Extensiones > Apps Script
A27: 2 | B27: Pendiente | C27: Copiar el código de 11_APPS_SCRIPT
A28: 3 | B28: Pendiente | C28: Configurar Script Properties sin exponer secretos
A29: 4 | B29: Pendiente | C29: Ejecutar setupTriggers() y autorizar
A30: 5 | B30: Pendiente | C30: Configurar WhatsApp Business + webhook
A31: 6 | B31: Pendiente | C31: Probar HOY, CAPTURA, HECHO y FOCO

Sheet 11_APPS_SCRIPT
A1: 11 — GOOGLE APPS SCRIPT (COPIAR EN EXTENSIONES > APPS SCRIPT)
A3: Este código activa recurrencias, Calendar y comandos bidireccionales por WhatsApp. Configure secretos solo en Project Settings > Script Properties.
A6: Línea | B6: Código
A7: 1 | B7: const CFG={AGENDA:'02_AGENDA',INBOX:'01_INBOX',RECUR:'03_RECURRENCIAS',DASH:'08_DASHBOARD'};
A8: 2 | B8: function p_(){return PropertiesService.getScriptProperties()}
A9: 3 | B9: function ss_(){const id=p_().getProperty('SHEET_ID');return id?SpreadsheetApp.openById(id):SpreadsheetApp.getActive()}
A10: 4 | B10: function tz_(){return p_().getProperty('TIMEZONE')||'America/Bogota'}
A11: 5 | B11: function v_(x){return x==null?'':String(x).trim()}
A12: 6 | B12: function dk_(d){return Utilities.formatDate(new Date(d),tz_(),'yyyy-MM-dd')}
A13: 7 | B13: function combine_(d,t){const x=new Date(d); if(t instanceof Date)x.setHours(t.getHours(),t.getMinutes(),0,0); return x}
A14: 8
A15: 9 | B15: function onOpen(){
A16: 10 | B16: SpreadsheetApp.getUi().createMenu('Asistente P95')
A17: 11 | B17: .addItem('Generar recurrencias','generateRecurringTasks')
A18: 12 | B18: .addItem('Sincronizar Calendar','syncAgendaToCalendar')
A19: 13 | B19: .addItem('Enviar brief','dailyBrief')
A20: 14 | B20: .addItem('Reporte semanal','weeklyReport')
A21: 15 | B21: .addSeparator().addItem('Instalar triggers','setupTriggers').addToUi();
A22: 16 | B22: }
A23: 17 | B23: function setupTriggers(){
A24: 18 | B24: const hs=['generateRecurringTasks','dailyBrief','upcomingAlerts','syncAgendaToCalendar','weeklyReport'];
A25: 19 | B25: ScriptApp.getProjectTriggers().forEach(t=>{if(hs.includes(t.getHandlerFunction()))ScriptApp.deleteTrigger(t)});
A26: 20 | B26: ScriptApp.newTrigger('generateRecurringTasks').timeBased().everyDays(1).atHour(5).nearMinute(15).create();
... A145: 139 | B145: }

Sheet 12_CONFIG
A1: 12 — ESTÁNDARES P95 CONFIGURABLES
A3: Métrica | B3: Meta inicial | C3: Peso índice | D3: Rango saludable | E3: Propósito | F3: Editable
A4: Ejecución de agenda | B4: 0.85 | C4: 0.25 | D4: >=85% | E4: Cerrar lo prometido | F4: Sí
A5: Foco profundo diario (min) | B5: 120 | C5: 0.2 | D5: >=120 | E5: Trabajo cognitivo sin interrupciones | F5: Sí
A6: Vencidas abiertas | B6: 2 | C6: 0.15 | D6: <=2 | E6: Backlog sano | F6: Sí
A7: Efectividad reuniones | B7: 4 | C7: 0.1 | D7: >=4/5 | E7: Reuniones con salida | F7: Sí
A8: Progreso OKR | B8: 0.7 | C8: 0.15 | D8: >=70% del plan | E8: Orientación a resultados | F8: Sí
A9: Ejecución semanal | B9: 0.8 | C9: 0.1 | D9: >=80% | E9: Consistencia | F9: Sí
A10: Revisión semanal | B10: 1 | C10: 0.05 | D10: 100% | E10: Aprendizaje/ajuste | F10: Sí
A12: “P95” significa estándar operativo interno exigente y configurable. No es una medición estadística contra pares ni garantiza superar al 95% de una población. Para percentil real se requiere una base comparable y métricas homogéneas.

Sheet 13_DOCUMENTACION
A1: 13 — DOCUMENTACIÓN, MÉTODO Y EVIDENCIA
A3: DISEÑO DEL SISTEMA
A4: Componente | B4: Implementación | C4: Por qué existe
A5: Timeboxing | B5: Bloques con inicio/fin + foco | C5: Protege trabajo importante
A6: Top 3 diario | B6: Plan recurrente | C6: Limita WIP y obliga a priorizar
A7: Si-entonces | B7: Recurrencias + reglas | C7: Convierte intención en conducta ejecutable
A8: Batching | B8: Inbox + ventanas de procesamiento | C8: Evita responder a cada estímulo
A9: Meeting hygiene | B9: Propósito + salida + duración | C9: Reduce reuniones sin resultado
A10: Weekly review | B10: Reporte + plan siguiente | C10: Cierra ciclos y corrige rumbo
A11: Human + agent | B11: WhatsApp como terminal | C11: Asistente en contexto móvil
A12: Control por resultados | B12: OKR + índice P95 | C12: No confundir actividad con avance
A14: EVIDENCIA Y REFERENCIAS
A15: Fuente | B15: Hallazgo usado | C15: URL
A16: Microsoft Work Trend Index 2025 | B16: Interrupciones frecuentes y elevada proporción de reuniones ad hoc en usuarios de alto volumen. | C16: https://www.microsoft.com/en-us/worklab/work-trend-index/2025-the-year-the-frontier-firm-is-born
A17: APA — Multitasking | B17: El cambio repetido de tarea añade costos cognitivos y reduce eficiencia. | C17: https://www.apa.org/topics/research/multitasking
A18: Gollwitzer & Sheeran | B18: Metaanálisis de 94 pruebas: efecto positivo medio-alto de implementation intentions sobre logro de metas. | C18: https://www.sciencedirect.com/science/article/abs/pii/S0065260106380021
A19: Google Calendar — Focus time | B19: Puede silenciar Chat y rechazar reuniones automáticamente en cuentas elegibles. | C19: https://support.google.com/calendar/answer/11190973
A20: Google Calendar — Time Insights | B20: Permite analizar tiempo de reuniones y concentración en cuentas elegibles. | C20: https://support.google.com/calendar/answer/10738043
A21: WhatsApp/Twilio | B21: Fuera de la ventana de servicio de 24 h, los mensajes proactivos requieren plantilla aprobada. | C21: https://www.twilio.com/docs/whatsapp/quickstart
A23: INSTALACIÓN EN 10 PASOS
A24: 1 | B24: Definir objetivos y metas en 05_OKR y 12_CONFIG.
A25: 2 | B25: Activar recurrencias en 03_RECURRENCIAS.
A26: 3 | B26: Activar reuniones solo si tienen propósito y salida.
A27: 4 | B27: Capturar todo primero en 01_INBOX.
A28: 5 | B28: Usar 02_AGENDA como única fuente de compromisos con fecha/hora.
A29: 6 | B29: Extensiones > Apps Script: copiar 11_APPS_SCRIPT.
A30: 7 | B30: Configurar Script Properties; nunca tokens en celdas.
A31: 8 | B31: Ejecutar setupTriggers() y autorizar.
A32: 9 | B32: Configurar WhatsApp Business/Cloud API y webhook.
A33: 10 | B33: Revisar Dashboard diario y Reportes semanal.
A35: LÍMITE DE ACTIVACIÓN: la hoja y el código quedan preparados, pero WhatsApp exige credenciales de WhatsApp Business/Cloud API (o proveedor equivalente), permisos y plantillas aprobadas para mensajes proactivos fuera de la ventana permitida. No almacene credenciales en esta hoja.
